Workbook
Name \0: #REF!
Name \0: #REF!
Name \0: #REF!
Name \0: #REF!
Name \0: #REF!
Name \0: #REF!
Name \a: #REF!
Name \a: #REF!
Name \a: #REF!
Name \a: #REF!
Name \a: #REF!
Name \a: #REF!
Name \e: #REF!
Name \e: #REF!
Name \e: #REF!
Name \e: #REF!
Name \e: #REF!
Name \e: #REF!
Name \p: #REF!
Name \p: #REF!
Name \p: #REF!
Name \p: #REF!
Name \p: #REF!
Name \p: #REF!
Name _______MA0001: #REF!
Name _______MA0001: #REF!
Name _______MA0001: #REF!
Name _______MA0001: #REF!
Name _______MA0001: #REF!
Name _______MA0001: #REF!
Name _______MO0001: #REF!
Name _______MO0001: #REF!
Name _______MO0001: #REF!
Name _______MO0001: #REF!
Name _______MO0001: #REF!
Name _______MO0001: #REF!
Name _______MO0002: #REF!
Name _______MO0002: #REF!
Name _______MO0002: #REF!
Name _______MO0002: #REF!
Name _______MO0002: #REF!
Name _______MO0002: #REF!
Name _______MO0003: #REF!
Name _______MO0003: #REF!
Name _______MO0003: #REF!
Name _______MO0003: #REF!
Name _______MO0003: #REF!
Name _______MO0003: #REF!
Name _______MO0004: #REF!
Name _______MO0004: #REF!
Name _______MO0004: #REF!
Name _______MO0004: #REF!
Name _______MO0004: #REF!
Name _______MO0004: #REF!
Name ______AUX1: #REF!
Name ______AUX1: #REF!
Name ______AUX1: #REF!
Name ______AUX1: #REF!
Name ______AUX1: #REF!
Name ______AUX1: #REF!

Sheet 1ª MEDIÇÃO EV - GAMERIM 
B2: 6 | F2: BOLETIM DE MEDIÇÃO
B8: CONTRATADA: | D8: GAMERIM TRANSPORTES | J8: OBRA: | K8: EV - ATA 97/2025 ; EV - 011/2026 | O8: PAGAMENTO: | P8: DEPÓSITO CONTA CORRENTE
B9: TIPO: | D9: TRANSPORTE DE CBUQ E AGREGADO | O9: PERÍODO: | P9: 01/02/2026 A 28/02/2026
B10: CPF / CNPJ | D10: 19.215.279/0001-30 | O10: EMISSÃO: | P10: 46091
B11: MEDIÇÃO: | D11: 1 | I11: MÊS: | J11: 46055 | O11: VENCIMENTO: | P11: 46122
B13: ITEM | C13: MATERIAL | E13: DISCRIMINAÇÃO | H13: UNIDADE DE MEDIDA | I13: PREÇO | J13: QUANTIDADE | K13: DIST. MÉDIA | L13: QUANTIDADES | O13: VALORES (R$)
I14: UNITÁRIO | J14: CONTRATADA | L14: MEDIÇÃO | M14: ANTERIOR | N14: ACUMULADA | O14: MEDIÇÃO | P14: ANTERIOR | Q14: ACUMULADO
B15: 1 | C15: C.B.U.Q | E15: TRANSPORTE DE CBUQ EV - ATA 97/2025 | H15: KM*TON | I15: ='REL. CAMIN. 1ª MED EV - GAMERIM'!L35 -> 0.7 | J15: ='REL. CAMIN. 1ª MED EV - GAMERIM'!J35 -> 522.33 | K15: ='REL. CAMIN. 1ª MED EV - GAMERIM'!K35 -> 44.668773 | L15: =J15 -> 522.33 | M15: 0 | N15: =L15+M15 -> 522.33 | O15: =J15*K15*I15 -> 16332.288 | P15: 0 | Q15: =O15+P15 -> 16332.288
B16: 2 | C16: C.B.U.Q | E16: TRANSPORTE DE CBUQ EV - C 011/2026 | H16: KM*TON | I16: ='REL. CAMIN. 1ª MED EV - GAMERIM'!L71 -> 0.7 | J16: ='REL. CAMIN. 1ª MED EV - GAMERIM'!J71 -> 722.11 | K16: ='REL. CAMIN. 1ª MED EV - GAMERIM'!K71 -> 49.460025 | L16: =J16 -> 722.11 | M16: 0 | N16: =L16+M16 -> 722.11 | O16: =J16*K16*I16 -> 25000.905 | P16: 0 | Q16: =O16+P16 -> 25000.905
B17: 3 | C17: - | E17: PEDÁGIO EV - C 011/2026 | H17: EIXO | I17: ='RELAÇÃO PEDÁGIO 1ª EV - GAMERIM'!K36 -> 12.100442 | J17: ='RELAÇÃO PEDÁGIO 1ª EV - GAMERIM'!J36 -> 113 | L17: =J17 -> 113 | M17: 0 | N17: =L17+M17 -> 113 | O17: =J17*I17 -> 1367.35 | P17: 0 | Q17: =O17+P17 -> 1367.35
B18: 4
B19: 5
B20: 6
B21: 7
L22: 0 | Q22: =IF(J22=0,"",I22*L22)
B23: TOTAL | O23: MEDIÇÃO | P23: ANTERIOR | Q23: ACUMULADO
O24: =SUM(O15:O21) -> 42700.543 | P24: =SUM(P15:P21) -> 0 | Q24: =SUM(Q15:Q21) -> 42700.543
B25: DEDUÇÕES
B26: ITEM | C26: DEDUÇÃO DE FORNECIMENTO DE MATERIAIS | O26: VALORES NESTA MEDIÇÃO | P26: VALORES ANTERIORES | Q26: VALORES ACUMULADOS
B27: 1 | C27: DESCONTOS - EV - C 011/2026 | O27: ='DESCONTO 1ª MEDIÇÃO EV- GAMERIM'!O72 -> 26072.541 | P27: 0 | Q27: =P27+O27 -> 26072.541
B28: 2 | C28: DESCONTOS EV - ATA 97/2025 | O28: ='DESCONTO 1ª MEDIÇÃO EV- GAMERIM'!O70 -> 16299.25 | P28: 0 | Q28: =P28+O28 -> 16299.25
B30: TOTAL | O30: =SUM(O27:O29) -> 42371.791 | P30: =SUM(P27:P29) -> 0 | Q30: =SUM(Q27:Q29) -> 42371.791
N32: VALORES LÍQUIDOS MEDIÇÃO DE PRESTAÇÃO DE SERVIÇO | O32: =O24-O30 -> 328.75232 | P32: =P24-P30 -> 0 | Q32: =Q24-Q30 -> 328.75232
B33: CRÉDITOS
B34: ITEM | C34: DISCRIMINAÇÃO | O34: VALOR
B36: TOTAL | O36: 0
B37: OBSERVAÇÕES:
B38: BANCO: BANCO SICREDI 748 | I38: TOTAL LÍQUIDO | O38: =O32+O36 -> 328.75232
B39: AGÊNCIA: 0730 | I39: Retenções | J39: ISSQN
B40: CONTA CORRENTE: 24804-8 | J40: INSS
B41: CNPJ: 19.215.297/0001-30 | J41: CONTRATUAL
I42: TOTAL A PAGAR >>> | O42: =O38-O39-O40-O41 -> 328.75232

Sheet REL. CAMIN. 1ª MED EV - GAMERIM
C5: DATA | D5: Nº TICKET | E5: OBRA | F5: PLACA | G5: FORNECEDOR | H5: MATERIAL | I5: UN. | J5: QUANT. | K5: DISTÂNCIA KM | L5: FRETE | N5: TOTAL
L6: R$ UNIT. | M6: R$ TOTAL | N6: R$ TOTAL
C8: RESUMO EV - ATA 097/2025
D9: Equipe EDINALDO
C10: 46064 | D10: TKB-040350 | E10: EV - ATA 097/2025 | F10: APL6A61 | G10: M.A.D.P | H10: C.B.U.Q. FAIXA "F" | J10: 21.4 | K10: 47 | L10: 0.7 | M10: =J10*K10*L10 -> 704.06 | N10: =M10 -> 704.06
C11: 46064 | D11: TKB-040334 | E11: EV - ATA 097/2025 | F11: ASZ2712 | G11: M.A.D.P | H11: C.B.U.Q. FAIXA "F" | J11: 20.2 | K11: 47 | L11: 0.7 | M11: =J11*K11*L11 -> 664.58 | N11: =M11 -> 664.58
C12: 46064 | D12: TKB-040341 | E12: EV - ATA 097/2025 | F12: MBU2710 | G12: M.A.D.P | H12: C.B.U.Q. FAIXA "F" | J12: 21.06 | K12: 47 | L12: 0.7 | M12: =J12*K12*L12 -> 692.874 | N12: =M12 -> 692.874
C13: 46064 | D13: TKB-040340 | E13: EV - ATA 097/2025 | F13: HQG6J32 | G13: M.A.D.P | H13: C.B.U.Q. FAIXA "F" | J13: 21.15 | K13: 47 | L13: 0.7 | M13: =J13*K13*L13 -> 695.835 | N13: =M13 -> 695.835
C14: 46064 | D14: TKB-040349 | E14: EV - ATA 097/2025 | F14: ASZ2712 | G14: M.A.D.P | H14: C.B.U.Q. FAIXA "F" | J14: 21.55 | K14: 47 | L14: 0.7 | M14: =J14*K14*L14 -> 708.995 | N14: =M14 -> 708.995
C15: 46064 | D15: TKB-040335 | E15: EV - ATA 097/2025 | F15: APL6A61 | G15: M.A.D.P | H15: C.B.U.Q. FAIXA "F" | J15: 22.05 | K15: 47 | L15: 0.7 | M15: =J15*K15*L15 -> 725.445 | N15: =M15 -> 725.445
C16: 46064 | D16: TKB-040338 | E16: EV - ATA 097/2025 | F16: ARP7879 | G16: M.A.D.P | H16: C.B.U.Q. FAIXA "F" | J16: 22.27 | K16: 47 | L16: 0.7 | M16: =J16*K16*L16 -> 732.683 | N16: =M16 -> 732.683
C17: 46065 | D17: TKB-040359 | E17: EV - ATA 097/2025 | F17: APL6A61 | G17: M.A.D.P | H17: C.B.U.Q. FAIXA "F" | J17: 23 | K17: 47 | L17: 0.7 | M17: =J17*K17*L17 -> 756.7 | N17: =M17 -> 756.7
C18: 46069 | D18: TKB-040405 | E18: EV - ATA 097/2025 | F18: APL6A61 | G18: M.A.D.P | H18: C.B.U.Q. FAIXA "F" | J18: 22.5 | K18: 47 | L18: 0.7 | M18: =J18*K18*L18 -> 740.25 | N18: =M18 -> 740.25
C19: 46069 | D19: TKB-040404 | E19: EV - ATA 097/2025 | F19: AUT5G68 | G19: M.A.D.P | H19: C.B.U.Q. FAIXA "C" | J19: 23.3 | K19: 47 | L19: 0.7 | M19: =J19*K19*L19 -> 766.57 | N19: =M19 -> 766.57
C20: 46071 | D20: TKB-040421 | E20: EV - ATA 097/2025 | F20: APL6A61 | G20: M.A.D.P | H20: C.B.U.Q. FAIXA "C" | J20: 21.4 | K20: 43 | L20: 0.7 | M20: =J20*K20*L20 -> 644.14 | N20: =M20 -> 644.14
C21: 46071 | D21: TKB-040426 | E21: EV - ATA 097/2025 | F21: ATN3B14 | G21: M.A.D.P | H21: C.B.U.Q. FAIXA "C" | J21: 23.65 | K21: 43 | L21: 0.7 | M21: =J21*K21*L21 -> 711.865 | N21: =M21 -> 711.865
... C31: 46072 | D31: TKB-040459 | E31: EV - ATA 097/2025 | F31: AUT5G68 | G31: M.A.D.P | H31: C.B.U.Q. FAIXA "C" | J31: 22.7 | K31: 42.9 | L31: 0.7 | M31: =J31*K31*L31 -> 681.681 | N31: =M31 -> 681.681
J35: =SUM(J10:J34) -> 522.33 | K35: =M35/J35/L35 -> 44.668773 | L35: 0.7 | M35: =SUM(M10:M34) -> 16332.288 | N35: =J35*K35*L35 -> 16332.288
C37: RESUMO EV - C 011/2025
D38: Equipe EDINALDO
C39: 46076 | D39: TKB-040511 | E39: EV - C 011/2025 | F39: MBU2710 | G39: M.A.D.P | H39: C.B.U.Q. FAIXA "C" | J39: 20.85 | K39: 62.6 | L39: 0.7 | M39: =J39*K39*L39 -> 913.647 | N39: =M39 -> 913.647
C40: 46076 | D40: TKB-040514 | E40: EV - C 011/2025 | F40: ARP7879 | G40: M.A.D.P | H40: C.B.U.Q. FAIXA "C" | J40: 21.65 | K40: 31.5 | L40: 0.7 | M40: =J40*K40*L40 -> 477.3825 | N40: =M40 -> 477.3825
C41: 46076 | D41: TKB-040509 | E41: EV - C 011/2025 | F41: HQG6J32 | G41: M.A.D.P | H41: C.B.U.Q. FAIXA "C" | J41: 21.88 | K41: 62.6 | L41: 0.7 | M41: =J41*K41*L41 -> 958.7816 | N41: =M41 -> 958.7816
C42: 46076 | D42: TKB-040505 | E42: EV - C 011/2025 | F42: AUJ2962 | G42: M.A.D.P | H42: C.B.U.Q. FAIXA "C" | J42: 22.05 | K42: 31.5 | L42: 0.7 | M42: =J42*K42*L42 -> 486.2025 | N42: =M42 -> 486.2025
C43: 46076 | D43: TKB-040501 | E43: EV - C 011/2025 | F43: APL6A61 | G43: M.A.D.P | H43: C.B.U.Q. FAIXA "C" | J43: 23.15 | K43: 31.5 | L43: 0.7 | M43: =J43*K43*L43 -> 510.4575 | N43: =M43 -> 510.4575
C44: 46076 | D44: TKB-040512 | E44: EV - C 011/2025 | F44: AUN7D32 | G44: M.A.D.P | H44: C.B.U.Q. FAIXA "C" | J44: 23.25 | K44: 62.6 | L44: 0.7 | M44: =J44*K44*L44 -> 1018.815 | N44: =M44 -> 1018.815
C45: 46076 | D45: TKB-040507 | E45: EV - C 011/2025 | F45: AWS5D97 | G45: M.A.D.P | H45: C.B.U.Q. FAIXA "C" | J45: 23.85 | K45: 62.6 | L45: 0.7 | M45: =J45*K45*L45 -> 1045.107 | N45: =M45 -> 1045.107
C46: 46077 | D46: TKB-040544 | E46: EV - C 011/2025 | F46: AOJ5E40 | G46: M.A.D.P | H46: C.B.U.Q. FAIXA "C" | J46: 21.1 | K46: 32.5 | L46: 0.7 | M46: =J46*K46*L46 -> 480.025 | N46: =M46 -> 480.025
C47: 46077 | D47: TKB-040541 | E47: EV - C 011/2025 | F47: APL6A61 | G47: M.A.D.P | H47: C.B.U.Q. FAIXA "C" | J47: 22.85 | K47: 32.5 | L47: 0.7 | M47: =J47*K47*L47 -> 519.8375 | N47: =M47 -> 519.8375
C48: 46077 | D48: TKB-040542 | E48: EV - C 011/2025 | F48: APP8D73 | G48: M.A.D.P | H48: C.B.U.Q. FAIXA "C" | J48: 23.02 | K48: 63.5 | L48: 0.7 | M48: =J48*K48*L48 -> 1023.239 | N48: =M48 -> 1023.239
C49: 46077 | D49: TKB-040549 | E49: EV - C 011/2025 | F49: ATN3B14 | G49: M.A.D.P | H49: C.B.U.Q. FAIXA "C" | J49: 24.15 | K49: 32.5 | L49: 0.7 | M49: =J49*K49*L49 -> 549.4125 | N49: =M49 -> 549.4125
C50: 46077 | D50: TKB-040551 | E50: EV - C 011/2025 | F50: ERD6B73 | G50: M.A.D.P | H50: C.B.U.Q. FAIXA "C" | J50: 25.65 | K50: 63.5 | L50: 0.7 | M50: =J50*K50*L50 -> 1140.1425 | N50: =M50 -> 1140.1425
... C69: 46081 | D69: TKB-040675 | E69: EV - C 011/2025 | F69: APL6A61 | G69: M.A.D.P | H69: C.B.U.Q. FAIXA "C" | J69: 23.65 | K69: 67.3 | L69: 0.7 | M69: =J69*K69*L69 -> 1114.1515 | N69: =M69 -> 1114.1515
J71: =SUM(J39:J70) -> 722.11 | K71: =M71/J71/L71 -> 49.460025 | L71: =L66 -> 0.7 | M71: =SUM(M39:M70) -> 25000.905 | N71: =J71*K71*L71 -> 25000.905
C74: TOTAL DE TRANSPORTE DE AGREGADO EV - C 97/2025 | N74: =M71 -> 25000.905
C75: TOTAL DE TRANSPORTE DE CARGAS EV - ATA 011/2026 | N75: =M35 -> 16332.288
C76: TOTAL DA MEDIÇÃO | N76: =SUM(N74:N75) -> 41333.193

Sheet RELAÇÃO PEDÁGIO 1ª EV - GAMERIM
C1: RELAÇÃO PEDÁGIOS
C5: DATA | D5: OBRA | E5: PLACA | F5: PRAÇA DE PEDÁGIO | G5: TRAÇÃO | H5: IDA (QUANTIDADE DE EIXOS) | I5: VOLTA(QUANTIDADE DE EIXOS) | J5: EIXO | K5: VALOR POR EIXO | L5: TOTAL
C7: EV - C 011/2026
C9: 46076 | D9: EV - C 11/2026 | E9: AWS5D67 | F9: CARAMBEI | J9: 5 | K9: =L9/J9 -> 12.1 | L9: 60.5
C10: 46076 | D10: EV - C 11/2026 | E10: HQG6J32 | F10: CARAMBEI | J10: 5 | K10: =L10/J10 -> 12.1 | L10: 60.5
C11: 46076 | D11: EV - C 11/2026 | E11: AUI2662 | F11: CARAMBEI | J11: 5 | K11: =L11/J11 -> 12.1 | L11: 60.5
C12: 46076 | D12: EV - C 11/2026 | E12: AJN7D32 | F12: CARAMBEI | J12: 5 | K12: =L12/J12 -> 12.1 | L12: 60.5
C13: 46076 | D13: EV - C 11/2026 | E13: MBU2710 | F13: CARAMBEI | J13: 5 | K13: =L13/J13 -> 12.1 | L13: 60.5
C14: 46077 | D14: EV - C 11/2026 | E14: ASE0E48 | F14: CARAMBEI | J14: 6 | K14: =L14/J14 -> 12.1 | L14: 72.6
C15: 46077 | D15: EV - C 11/2026 | E15: ERD6B73 | F15: CARAMBEI | J15: 5 | K15: =L15/J15 -> 12.1 | L15: 60.5
C16: 46077 | D16: EV - C 11/2026 | E16: MDG7G14 | F16: CARAMBEI | J16: 6 | K16: =L16/J16 -> 12.1 | L16: 72.6
C17: 46077 | D17: EV - C 11/2026 | E17: APP8D73 | F17: CARAMBEI | J17: 5 | K17: =L17/J17 -> 12.1 | L17: 60.5
C18: 46077 | D18: EV - C 11/2026 | E18: ATN3B14 | F18: CARAMBEI | J18: 4 | K18: =L18/J18 -> 12.1 | L18: 48.4
C19: 46078 | D19: EV - C 11/2026 | E19: RXX6A82 | F19: CARAMBEI | J19: 7 | K19: =L19/J19 -> 12.1 | L19: 84.7
C20: 46078 | D20: EV - C 11/2026 | E20: APL6A61 | F20: CARAMBEI | J20: 5 | K20: =L20/J20 -> 12.1 | L20: 60.5
... C30: 46080 | D30: EV - C 11/2026 | E30: AJN7D32 | F30: CARAMBEI | J30: 5 | K30: =L30/J30 -> 12.1 | L30: 60.5
C33: DESCONTOS: EV - C 11/2026 | J33: =SUM(J9:J32) -> 113 | K33: =L33/J33 -> 12.100442 | L33: =SUM(L9:L32) -> 1367.35
C36: PEDÁGIOS EV - 011/2026 | J36: =SUM(J9:J30) -> 113 | K36: =K33 -> 12.100442 | L36: =J36*K36 -> 1367.35
C38: TOTAL DE DESCONTOS DE PEDÁGIO DESTA MEDIÇÃO =====>>> | L38: =L36 -> 1367.35
M97: =J97*K97*L97 -> 0
M98: =J98*K98*L98 -> 0
M99: =J99*K99*L99 -> 0
M100: =J100*K100*L100 -> 0
M101: =J101*K101*L101 -> 0
M102: =J102*K102*L102 -> 0
J103: 11.9 | M103: =J103*K103*L103 -> 0
K108: 218.3
K109: 218.3 | M109: =J109*K109*L109 -> 0
K112: 215.3
K113: 215.3

Sheet DESCONTO 1ª MEDIÇÃO EV- GAMERIM
B1: DESCONTOS DE COMBUSTÍVEL
B5: OBRA | C5: DATA | D5: Nº CUPOM FISCAL | E5: Nº REQ. | F5: EMPRESA | G5: DATA EMISSÃO | H5: NOTA FISCAL | I5: PLACA | J5: FORNECEDOR | K5: COMBUSTÍVEL | L5: UN. | M5: QUANT. | N5: VALOR UNITÁRIO | O5: SUBTOTAL | P5: TOTAL
B7: RESUMO - DESCONTOS - EV - C 011/2026
B9: EV - C 011/2026 | C9: 46073 | D9: 518571 | E9: 2958 | F9: GAISSLER | G9: 46084 | H9: 27866 | I9: RXX6A82 | J9: POSTO POTÊNCIA | K9: DIESEL S10 | L9: L | M9: 200.011 | N9: 5.69 | O9: 1138.06 | P9: =O9 -> 1138.06
B10: EV - C 011/2026 | C10: 46073 | D10: 518574 | E10: 2959 | F10: GAISSLER | G10: 46084 | H10: 27866 | I10: APP8D 73 | J10: POSTO POTÊNCIA | K10: DIESEL S500 | L10: L | M10: 115.013 | N10: 5.59 | O10: 642.92 | P10: =O10 -> 642.92
B11: EV - C 011/2026 | C11: 46073 | D11: 27262 | E11: 2960 | F11: GAISSLER | G11: 46073 | H11: 27262 | I11: AUJ-2962 | J11: POSTO POTÊNCIA | K11: DIESEL S500 | L11: L | M11: 200 | N11: 5.59 | O11: 1118 | P11: =O11 -> 1118
B12: EV - C 011/2026 | C12: 46073 | D12: 518810 | E12: 2961 | F12: GAISSLER | G12: 46084 | H12: 27866 | I12: MDG7 G14 | J12: POSTO POTÊNCIA | K12: DIESEL S500 | L12: L | M12: 186.383 | N12: 5.59 | O12: 1041.88 | P12: =O12 -> 1041.88
B13: EV - C 011/2026 | C13: 46076 | D13: 520044 | E13: 2966 | F13: GAISSLER | G13: 46084 | H13: 27866 | I13: MBU6D28 | J13: POSTO POTÊNCIA | K13: DIESEL S500 | L13: L | M13: 174.211 | N13: 5.59 | O13: 973.83949 | P13: =O13 -> 973.83949
B14: EV - C 011/2026 | C14: 46077 | D14: 520265 | E14: 2968 | F14: GAISSLER | G14: 46084 | H14: 27866 | I14: AOJ5E 40 | J14: POSTO POTÊNCIA | K14: DIESEL S10 | L14: L | M14: 157.002 | N14: 5.69 | O14: 893.34138 | P14: =O14 -> 893.34138
B15: EV - C 011/2026 | C15: 46077 | D15: 520430 | E15: 2970 | F15: GAISSLER | G15: 46084 | H15: 27866 | I15: AUN7 D32 | J15: POSTO POTÊNCIA | K15: DIESEL S500 | L15: L | M15: 300 | N15: 5.59 | O15: 1677 | P15: =O15 -> 1677
B16: EV - C 011/2026 | C16: 46077 | D16: 520491 | E16: 2972 | F16: GAISSLER | G16: 46084 | H16: 27866 | I16: AWS5D97 | J16: POSTO POTÊNCIA | K16: DIESEL S10 | L16: L | M16: 154.954 | N16: 5.69 | O16: 881.69 | P16: =O16 -> 881.69
B17: EV - C 011/2026 | C17: 46077 | D17: 520545 | E17: 2973 | F17: GAISSLER | G17: 46084 | H17: 27866 | I17: ERD6 B73 | J17: POSTO POTÊNCIA | K17: DIESEL S10 | L17: L | M17: 194.098 | N17: 5.69 | O17: 1104.19 | P17: =O17 -> 1104.19
B18: EV - C 011/2026 | C18: 46077 | D18: 520550 | E18: 2974 | F18: GAISSLER | G18: 46084 | H18: 27866 | I18: BSF5I16 | J18: POSTO POTÊNCIA | K18: DIESEL S500 | L18: L | M18: 79.948122 | N18: 5.59 | O18: 446.91 | P18: =O18 -> 446.91
B19: EV - C 011/2026 | C19: 46077 | D19: 520691 | E19: 2976 | F19: GAISSLER | G19: 46084 | H19: 27866 | I19: ATN3 B14 | J19: POSTO POTÊNCIA | K19: DIESEL S10 | L19: L | M19: 152.069 | N19: 5.69 | O19: 865.27 | P19: =O19 -> 865.27
B20: EV - C 011/2026 | C20: 46078 | D20: 520694 | E20: 2977 | F20: GAISSLER | G20: 46084 | H20: 27866 | I20: HQG6J32 | J20: POSTO POTÊNCIA | K20: DIESEL S500 | L20: L | M20: 150 | N20: 5.59 | O20: 838.5 | P20: =O20 -> 838.5
... B35: EV - C 011/2026 | C35: 46080 | D35: 521913 | E35: 2997 | F35: GAISSLER | G35: 46084 | H35: 27866 | I35: BSF5I16 | J35: POSTO POTÊNCIA | K35: DIESEL S500 | L35: L | M35: 100.088 | N35: 5.59 | O35: 559.49 | P35: =O35 -> 559.49
B36: EV - C 011/2026 | C36: 46072 | D36: 518406 | E36: 2955 | F36: GAISSLER | G36: 46084 | H36: 27866 | I36: EWU-6C38 | J36: POSTO POTÊNCIA | K36: DIESEL S10 | L36: L | M36: 300 | N36: 5.69 | O36: 1707 | P36: 1707
B37: EV - C 011/2026 | C37: 46072 | D37: 518569 | E37: 2957 | F37: GAISSLER | G37: 46084 | H37: 27866 | I37: AOJ5E 40 | J37: POSTO POTÊNCIA | K37: DIESEL S10 | L37: L | M37: 120.288 | N37: 5.69 | O37: 684.44 | P37: 684.44
B38: EV - C 011/2026 | C38: 46066 | D38: 515600 | E38: 2872 | F38: GAISSLER | G38: 46072 | H38: 27186 | I38: ATN3 B14 | J38: POSTO POTÊNCIA | K38: DIESEL S10 | L38: L | M38: 115.002 | N38: 5.69 | O38: 654.36 | P38: 654.36
B41: DESCONTOS - EV - C 011/2026 | O41: =SUM(P9:P40) -> 26072.541
B43: RESUMO - DESCONTOS EV - ATA 97/2025
B45: EV - C ATA97/2025 | C45: 46063 | D45: 513983 | E45: 2839 | F45: GAISSLER | G45: 46072 | H45: 27186 | I45: JBD2H88 | J45: POSTO POTÊNCIA | K45: DIESEL S10 | L45: L | M45: 170.35 | N45: 5.69 | O45: 969.29 | P45: =O45 -> 969.29
B46: EV - C ATA97/2025 | C46: 46063 | D46: 513983 | E46: 2840 | F46: GAISSLER | G46: 46072 | H46: 27186 | I46: JBD2H88 | J46: POSTO POTÊNCIA | K46: ARLA 32 | L46: L | M46: 34 | N46: 3.09 | O46: 105.06 | P46: =O46 -> 105.06
B47: EV - C ATA97/2025 | C47: 46063 | D47: 513984 | E47: 2841 | F47: GAISSLER | G47: 46072 | H47: 27186 | I47: ERD6 B73 | J47: POSTO POTÊNCIA | K47: DIESEL S10 | L47: L | M47: 170.078 | N47: 5.69 | O47: 967.74 | P47: =O47 -> 967.74
B48: EV - C ATA97/2025 | C48: 46064 | D48: 514382 | E48: 2844 | F48: GAISSLER | G48: 46072 | H48: 27186 | I48: HQG6J32 | J48: POSTO POTÊNCIA | K48: DIESEL S500 | L48: L | M48: 100 | N48: 5.59 | O48: 559 | P48: =O48 -> 559
B49: EV - C ATA97/2025 | C49: 46064 | D49: 514494 | E49: 2845 | F49: GAISSLER | G49: 46072 | H49: 27186 | I49: MDG7 G14 | J49: POSTO POTÊNCIA | K49: DIESEL S500 | L49: L | M49: 100 | N49: 5.59 | O49: 559 | P49: =O49 -> 559
B50: EV - C ATA97/2025 | C50: 46064 | D50: 514764 | E50: 2854 | F50: GAISSLER | G50: 46072 | H50: 27186 | I50: MCD8I20 | J50: POSTO POTÊNCIA | K50: DIESEL S500 | L50: L | M50: 180.073 | N50: 5.59 | O50: 1006.61 | P50: =O50 -> 1006.61
B51: EV - C ATA97/2025 | C51: 46066 | D51: 515428 | E51: 2871 | F51: GAISSLER | G51: 46072 | H51: 27186 | I51: MBU6D28 | J51: POSTO POTÊNCIA | K51: DIESEL S500 | L51: L | M51: 87.109 | N51: 5.59 | O51: 486.94 | P51: 486.94
B52: EV - C ATA97/2025 | C52: 46069 | D52: 516937 | E52: 2940 | F52: GAISSLER | G52: 46084 | H52: 27866 | I52: RXX6A82 | J52: POSTO POTÊNCIA | K52: DIESEL S10 | L52: L | M52: 143.86995 | N52: 5.69 | O52: 818.62 | P52: 818.62
B53: EV - C ATA97/2025 | C53: 46069 | D53: 516937 | E53: 2941 | F53: GAISSLER | G53: 46084 | H53: 27866 | I53: RXX6A82 | J53: POSTO POTÊNCIA | K53: ARLA 32 | L53: L | M53: 19 | N53: 3.09 | O53: 58.71 | P53: 58.71
B54: EV - C ATA97/2025 | C54: 46069 | D54: 516992 | E54: 2942 | F54: GAISSLER | G54: 46084 | H54: 27866 | I54: ARP-7879 | J54: POSTO POTÊNCIA | K54: DIESEL S500 | L54: L | M54: 161.485 | N54: 5.59 | O54: 902.7 | P54: 902.7
B55: EV - C ATA97/2025 | C55: 46069 | D55: 517123 | E55: 2943 | F55: GAISSLER | G55: 46084 | H55: 27866 | I55: BSF5I16 | J55: POSTO POTÊNCIA | K55: DIESEL S500 | L55: L | M55: 100 | N55: 5.59 | O55: 559 | P55: 559
B56: EV - C ATA97/2025 | C56: 46070 | D56: 517138 | E56: 2944 | F56: GAISSLER | G56: 46084 | H56: 27866 | I56: ATN3 B14 | J56: POSTO POTÊNCIA | K56: DIESEL S10 | L56: L | M56: 100 | N56: 5.69 | O56: 569 | P56: 569
B57: EV - C ATA97/2025 | C57: 46070 | D57: 517634 | E57: 2945 | F57: GAISSLER | G57: 46084 | H57: 27866 | I57: APP8D 73 | J57: POSTO POTÊNCIA | K57: DIESEL S500 | L57: L | M57: 230.013 | N57: 5.59 | O57: 1285.77 | P57: 1285.77
B58: EV - C ATA97/2025 | C58: 46070 | D58: 517672 | E58: 2946 | F58: GAISSLER | G58: 46084 | H58: 27866 | I58: FDB0C74 | J58: POSTO POTÊNCIA | K58: DIESEL S10 | L58: L | M58: 200 | N58: 5.69 | O58: 1138 | P58: 1138
B59: EV - C ATA97/2025 | C59: 46070 | D59: 517673 | E59: 2947 | F59: GAISSLER | G59: 46084 | H59: 27866 | I59: EWU-6C38 | J59: POSTO POTÊNCIA | K59: DIESEL S10 | L59: L | M59: 200 | N59: 5.69 | O59: 1138 | P59: 1138
B60: EV - C ATA97/2025 | C60: 46071 | D60: 517679 | E60: 2948 | F60: GAISSLER | G60: 46084 | H60: 27866 | I60: ASD2F 97 | J60: POSTO POTÊNCIA | K60: DIESEL S10 | L60: L | M60: 200 | N60: 5.69 | O60: 1138 | P60: 1138
B61: EV - C ATA97/2025 | C61: 46071 | D61: 517983 | E61: 2950 | F61: GAISSLER | G61: 46084 | H61: 27866 | I61: HQG6J32 | J61: POSTO POTÊNCIA | K61: DIESEL S500 | L61: L | M61: 150.131 | N61: 5.59 | O61: 839.24 | P61: 839.24
B62: EV - C ATA97/2025 | C62: 46072 | D62: 517987 | E62: 2951 | F62: GAISSLER | G62: 46084 | H62: 27866 | I62: MBU-2710 | J62: POSTO POTÊNCIA | K62: DIESEL S500 | L62: L | M62: 150 | N62: 5.59 | O62: 838.5 | P62: 838.5
... B65: EV - C ATA97/2025 | C65: 46072 | D65: 518377 | E65: 2954 | F65: GAISSLER | G65: 46084 | H65: 27866 | I65: ASE0E 48 | J65: POSTO POTÊNCIA | K65: DIESEL S10 | L65: L | M65: 220.011 | N65: 5.69 | O65: 1251.86 | P65: 1251.86
...

Sheet 2ª MEDIÇÃO EV - GAMERIM 
B2: #VALUE! | F2: BOLETIM DE MEDIÇÃO
B8: CONTRATADA: | D8: GAMERIM TRANSPORTES | J8: OBRA: | K8: EV - 011/2026 | O8: PAGAMENTO: | P8: DEPÓSITO CONTA CORRENTE
B9: TIPO: | D9: TRANSPORTE DE CBUQ E AGREGADO | O9: PERÍODO: | P9: 01/03/2026 A 31/03/2026
B10: CPF / CNPJ | D10: 19.215.279/0001-30 | O10: EMISSÃO: | P10: 46128
B11: MEDIÇÃO: | D11: 2 | I11: MÊS: | J11: 46084 | O11: VENCIMENTO: | P11: 46152
B13: ITEM | C13: MATERIAL | E13: DISCRIMINAÇÃO | H13: UNIDADE DE MEDIDA | I13: PREÇO | J13: QUANTIDADE | K13: DIST. MÉDIA | L13: QUANTIDADES | O13: VALORES (R$)
I14: UNITÁRIO | J14: CONTRATADA | L14: MEDIÇÃO | M14: ANTERIOR | N14: ACUMULADA | O14: MEDIÇÃO | P14: ANTERIOR | Q14: ACUMULADO
B15: 1 | C15: C.B.U.Q | E15: TRANSPORTE DE CBUQ EV - ATA 97/2025 | H15: KM*TON | M15: ='1ª MEDIÇÃO EV - GAMERIM '!L15 -> 522.33 | N15: =L15+M15 -> 522.33 | P15: ='1ª MEDIÇÃO EV - GAMERIM '!O15 -> 16332.288 | Q15: =O15+P15 -> 16332.288
B16: 2 | C16: C.B.U.Q | E16: TRANSPORTE DE CBUQ EV - C 011/2026 | H16: KM*TON | I16: ='REL. CAMIN. 2ª MED EV - GAMERIM'!L166 -> 0.86 | J16: ='REL. CAMIN. 2ª MED EV - GAMERIM'!J166 -> 3701.57 | K16: ='REL. CAMIN. 2ª MED EV - GAMERIM'!K166 -> 48.715925 | L16: =J16 -> 3701.57 | M16: ='1ª MEDIÇÃO EV - GAMERIM '!L16 -> 722.11 | N16: =L16+M16 -> 4423.68 | O16: =J16*K16*I16 -> 155079.85 | P16: ='1ª MEDIÇÃO EV - GAMERIM '!O16 -> 25000.905 | Q16: =O16+P16 -> 180080.75
B17: 3 | C17: - | E17: PEDÁGIO EV - C 011/2026 | H17: EIXO | I17: ='RELAÇÃO PEDÁGIO 2ª EV - GAMERIM'!J95 -> 12.1 | J17: ='RELAÇÃO PEDÁGIO 2ª EV - GAMERIM'!I92 -> 382.00826 | L17: =J17 -> 382.00826 | M17: ='1ª MEDIÇÃO EV - GAMERIM '!L17 -> 113 | N17: =L17+M17 -> 495.00826 | O17: =J17*I17 -> 4622.3 | P17: ='1ª MEDIÇÃO EV - GAMERIM '!O17 -> 1367.35 | Q17: =O17+P17 -> 5989.65
B18: 4 | C18: FRESADO | E18: HORA FRESA | H18: HORA | I18: ='REL. CAMIN. 2ª MED EV - GAMERIM'!L178 -> 156.25 | J18: ='REL. CAMIN. 2ª MED EV - GAMERIM'!K178 -> 18 | L18: =J18 -> 18 | N18: =L18+M18 -> 18 | O18: =I18*L18 -> 2812.5 | Q18: =O18+P18 -> 2812.5
L26: 0 | Q26: =IF(J26=0,"",I26*L26)
B27: TOTAL | O27: MEDIÇÃO | P27: ANTERIOR | Q27: ACUMULADO
O28: =SUM(O15:O25) -> 162514.65 | P28: =SUM(P15:P17) -> 42700.543 | Q28: =P28+O28 -> 205215.19
B29: DEDUÇÕES
B30: ITEM | C30: DEDUÇÃO DE FORNECIMENTO DE MATERIAIS | O30: VALORES NESTA MEDIÇÃO | P30: VALORES ANTERIORES | Q30: VALORES ACUMULADOS
B31: 1 | C31: DESCONTOS - EV - C 011/2026 | O31: ='[1]DIESEL '!O65 -> 56321.715 | P31: ='1ª MEDIÇÃO EV - GAMERIM '!O27 -> 26072.541 | Q31: =P31+O31 -> 82394.256
B32: 2 | C32: DESCONTOS EV - ATA 97/2025 | O32: 0 | P32: ='1ª MEDIÇÃO EV - GAMERIM '!O28 -> 16299.25 | Q32: =O32+P32 -> 16299.25
B34: TOTAL | O34: =SUM(O31:O33) -> 56321.715 | P34: =SUM(P31:P33) -> 42371.791 | Q34: =SUM(Q31:Q33) -> 98693.506
N36: VALORES LÍQUIDOS MEDIÇÃO DE PRESTAÇÃO DE SERVIÇO | O36: =O28-O34 -> 106192.93 | P36: 0 | Q36: =Q28-Q34 -> 106521.69
B37: CRÉDITOS
B38: ITEM | C38: DISCRIMINAÇÃO | O38: VALOR
B40: TOTAL | O40: 0
B41: OBSERVAÇÕES:
B42: BANCO: BANCO SICREDI 748 | I42: TOTAL LÍQUIDO | O42: =O36+O40 -> 106192.93
B43: AGÊNCIA: 0730 | I43: Retenções | J43: ISSQN
B44: CONTA CORRENTE: 24804-8 | J44: INSS
B45: CNPJ: 19.215.297/0001-30 | J45: CONTRATUAL
I46: TOTAL A PAGAR >>> | O46: =O42-O43-O44-O45 -> 106192.93
C47: Data:___/____/_____ | G47: Data: _____/____/_____ | I47: Data: _____/____/_____ | L47: Data: _____/____/_____ | O47: Data: _____/____/_____
C51: _________________________________________ | G51: ________________________________________ | I51: __________________________________ | L51: __________________________________ | O51: ________________________________
C52: ELABORADO POR: | G52: PRESTADOR: | I52: GERENTE REGIONAL: | L52: GERENTE RESPONSÁVEL:: | O52: DIRETORIA
C53: EDUARDO SAMPAIO | G53: GAMERIM TRANSPORTES | O53: EVENTO CONSTRUTORA

Sheet REL. CAMIN. 2ª MED EV - GAMERIM
C5: DATA | D5: Nº TICKET | E5: OBRA | F5: PLACA | G5: FORNECEDOR | H5: MATERIAL | I5: UN. | J5: QUANT. | K5: DISTÂNCIA KM | L5: FRETE | N5: TOTAL
L6: R$ UNIT. | M6: R$ TOTAL | N6: R$ TOTAL
C8: RESUMO EV - C 011/2026
D9: Equipe EDINALDO
C10: 46083 | D10: TKB-040704 | E10: EV - C 011/2026 | F10: BTO4E72 | G10: M.A.D.P | H10: C.B.U.Q. FAIXA "C" | I10: TON | J10: 21.1 | K10: 65.7 | L10: 0.7 | M10: =J10*K10*L10 -> 970.389 | N10: =M10 -> 970.389
C11: 46083 | D11: TKB-040708 | E11: EV - C 011/2026 | F11: AUJ2962 | G11: M.A.D.P | H11: C.B.U.Q. FAIXA "C" | I11: TON | J11: 21.25 | K11: 65.7 | L11: 0.7 | M11: =J11*K11*L11 -> 977.2875 | N11: =M11 -> 977.2875
C12: 46083 | D12: TKB-040697 | E12: EV - C 011/2026 | F12: AUJ2962 | G12: M.A.D.P | H12: C.B.U.Q. FAIXA "C" | I12: TON | J12: 21.8 | K12: 31.5 | L12: 0.7 | M12: =J12*K12*L12 -> 480.69 | N12: =M12 -> 480.69
C13: 46083 | D13: TKB-040712 | E13: EV - C 011/2026 | F13: APL6A61 | G13: M.A.D.P | H13: C.B.U.Q. FAIXA "C" | I13: TON | J13: 22.9 | K13: 31.5 | L13: 0.7 | M13: =J13*K13*L13 -> 504.945 | N13: =M13 -> 504.945
C14: 46083 | D14: TKB-040692 | E14: EV - C 011/2026 | F14: APL6A61 | G14: M.A.D.P | H14: C.B.U.Q. FAIXA "C" | I14: TON | J14: 23.1 | K14: 31.5 | L14: 0.7 | M14: =J14*K14*L14 -> 509.355 | N14: =M14 -> 509.355
C15: 46083 | D15: TKB-040694 | E15: EV - C 011/2026 | F15: BTO4E72 | G15: M.A.D.P | H15: C.B.U.Q. FAIXA "C" | I15: TON | J15: 23.36 | K15: 31.5 | L15: 0.7 | M15: =J15*K15*L15 -> 515.088 | N15: =M15 -> 515.088
C16: 46083 | D16: TKB-040698 | E16: EV - C 011/2026 | F16: ASE0E48 | G16: M.A.D.P | H16: C.B.U.Q. FAIXA "C" | I16: TON | J16: 28.92 | K16: 65.7 | L16: 0.7 | M16: =J16*K16*L16 -> 1330.0308 | N16: =M16 -> 1330.0308
C17: 46084 | D17: TKB-040740 | E17: EV - C 011/2026 | F17: MDG7G14 | G17: M.A.D.P | H17: C.B.U.Q. FAIXA "C" | I17: TON | J17: 20.95 | K17: 65.7 | L17: 0.7 | M17: =J17*K17*L17 -> 963.4905 | N17: =M17 -> 963.4905
C18: 46084 | D18: TKB-040728 | E18: EV - C 011/2026 | F18: APL6A61 | G18: M.A.D.P | H18: C.B.U.Q. FAIXA "C" | I18: TON | J18: 23 | K18: 31.5 | L18: 0.7 | M18: =J18*K18*L18 -> 507.15 | N18: =M18 -> 507.15
C19: 46084 | D19: TKB-040737 | E19: EV - C 011/2026 | F19: BSF5I16 | G19: M.A.D.P | H19: C.B.U.Q. FAIXA "C" | I19: TON | J19: 23.09 | K19: 65.7 | L19: 0.7 | M19: =J19*K19*L19 -> 1061.9091 | N19: =M19 -> 1061.9091
C20: 46084 | D20: TKB-040729 | E20: EV - C 011/2026 | F20: ATN3B14 | G20: M.A.D.P | H20: C.B.U.Q. FAIXA "C" | I20: TON | J20: 24.15 | K20: 31.5 | L20: 0.7 | M20: =J20*K20*L20 -> 532.5075 | N20: =M20 -> 532.5075
C21: 46084 | D21: TKB-040732 | E21: EV - C 011/2026 | F21: ERD6B73 | G21: M.A.D.P | H21: C.B.U.Q. FAIXA "C" | I21: TON | J21: 24.8 | K21: 31.5 | L21: 0.7 | M21: =J21*K21*L21 -> 546.84 | N21: =M21 -> 546.84
... C163: 46111 | D163: TKB-041314 | E163: EV - C 011/2026 | F163: BEA8D25 | G163: M.A.D.P | H163: C.B.U.Q. FAIXA "C" | I163: TON | J163: 39.15 | K163: 46.2 | L163: 0.98 | M163: =J163*K163*L163 -> 1772.5554 | N163: =M163 -> 1772.5554
J166: =SUM(J10:J163) -> 3701.57 | K166: =M166/J166/L166 -> 48.715925 | L166: 0.86 | M166: =SUM(M10:M165) -> 155079.85 | N166: =J166*K166*L166 -> 155079.85
C167: CAMINHAO NA FRESA ( DIARIA R$ 1.250,00 )
C169: 46086 | E169: EV - C 011/2026 | F169: ASE0E48 | H169: FREESADO | K169: 2 | L169: 156.25 | M169: =K169*L169 -> 312.5 | N169: =L169*K169 -> 312.5
C170: 46085 | E170: EV - C 011/2026 | F170: MBU2710 | H170: FREESADO | K170: 8 | L170: 156.25 | M170: =K170*L170 -> 1250 | N170: =L170*K170 -> 1250
C171: 46094 | E171: EV - C 011/2026 | F171: APL6A61 | H171: FREESADO | K171: 8 | L171: 156.25 | M171: =K171*L171 -> 1250 | N171: =L171*K171 -> 1250
J178: =SUM(J168:J177) -> 0 | K178: =SUM(K169:K171) -> 18 | L178: =L171 -> 156.25 | M178: =SUM(M168:M177) -> 2812.5 | N178: =L178*K178 -> 2812.5
C181: CAMINHAO NA FRESA ( DIARIA R$ 1.250,00 ) | N181: =N178 -> 2812.5
C183: TOTAL DE TRANSPORTE DE CARGAS EV - ATA 011/2026 | N183: =M166 -> 155079.85
C184: TOTAL DA MEDIÇÃO | N184: =SUM(N181:N183) -> 157892.35

Sheet RELAÇÃO PEDÁGIO 2ª EV - GAMERIM
B1: RELAÇÃO PEDÁGIOS
B5: DATA | C5: OBRA | D5: PLACA | E5: PRAÇA DE PEDÁGIO | F5: TRAÇÃO | G5: IDA (QUANTIDADE DE EIXOS) | H5: VOLTA(QUANTIDADE DE EIXOS) | I5: EIXO | J5: VALOR POR EIXO | K5: TOTAL
B7: EV - C 011/2026
B9: 46084 | C9: EV - C 11/2026 | D9: MDG-7G14 | E9: CARAMBEI | I9: =K9/J9 -> 6 | J9: 12.1 | K9: 72.6
B10: 46085 | C10: EV - C 11/2026 | D10: AUN-7D32 | E10: CARAMBEI | I10: =K10/J10 -> 5 | J10: 12.1 | K10: 60.5
B11: 46083 | C11: EV - C 11/2026 | D11: BTO4E72 | E11: CARAMBEI | I11: =K11/J11 -> 5 | J11: 12.1 | K11: 60.5
B12: 46087 | C12: EV - C 11/2026 | D12: BTO4E72 | E12: CARAMBEI | I12: =K12/J12 -> 5 | J12: 12.1 | K12: 60.5
B13: 46094 | C13: EV - C 11/2026 | D13: ATZ0091 | E13: CARAMBEI | I13: =K13/J13 -> 6 | J13: 12.1 | K13: 72.6
B14: 46107 | C14: EV - C 11/2026 | D14: ATZ0091 | E14: CARAMBEI | I14: =K14/J14 -> 6 | J14: 12.1 | K14: 72.6
B15: 46101 | C15: EV - C 11/2026 | D15: ERD6B73 | E15: CARAMBEI | I15: =K15/J15 -> 5 | J15: 12.1 | K15: 60.5
B16: 46108 | C16: EV - C 11/2026 | D16: ERD6B73 | E16: CARAMBEI | I16: =K16/J16 -> 5 | J16: 12.1 | K16: 60.5
B17: 46085 | C17: EV - C 11/2026 | D17: AWSSD97 | E17: CARAMBEI | I17: =K17/J17 -> 5 | J17: 12.1 | K17: 60.5
B18: 46088 | C18: EV - C 11/2026 | D18: AWSSD97 | E18: CARAMBEI | I18: =K18/J18 -> 5 | J18: 12.1 | K18: 60.5
B19: 46084 | C19: EV - C 11/2026 | D19: BSF5I16 | E19: CARAMBEI | I19: =K19/J19 -> 5 | J19: 12.1 | K19: 60.5
B20: 46099 | C20: EV - C 11/2026 | D20: BSF5I16 | E20: CARAMBEI | I20: =K20/J20 -> 4 | J20: 12.1 | K20: 48.4
... B90: 46108 | C90: EV - C 11/2026 | D90: BUD-7C80 | E90: CARAMBEI | I90: =K90/J90 -> 4 | J90: 12.1 | K90: 48.4
B92: DESCONTOS: EV - C 11/2026 | I92: =SUM(I9:I90) -> 382.00826 | J92: =K92/I92 -> 12.1 | K92: =SUM(K9:K90) -> 4622.3
B95: PEDÁGIOS EV - 011/2026 | I95: =I92 -> 382.00826 | J95: =J92 -> 12.1 | K95: =I95*J95 -> 4622.3
B97: TOTAL DE DESCONTOS DE PEDÁGIO DESTA MEDIÇÃO =====>>> | K97: =K95 -> 4622.3
L156: =I156*J156*K156 -> 0
L157: =I157*J157*K157 -> 0
L158: =I158*J158*K158 -> 0
L159: =I159*J159*K159 -> 0
L160: =I160*J160*K160 -> 0
L161: =I161*J161*K161 -> 0
I162: 11.9 | L162: =I162*J162*K162 -> 0
J167: 218.3
J168: 218.3 | L168: =I168*J168*K168 -> 0
J171: 215.3
J172: 215.3

Sheet DESCONTO 2ª MEDIÇÃO EV- GAMERIM
B1: DESCONTOS DE COMBUSTÍVEL
B5: OBRA | C5: DATA | D5: Nº CUPOM FISCAL | E5: Nº REQ. | F5: EMPRESA | G5: DATA EMISSÃO | H5: NOTA FISCAL | I5: PLACA | J5: FORNECEDOR | K5: COMBUSTÍVEL | L5: UN. | M5: QUANT. | N5: VALOR UNITÁRIO | O5: SUBTOTAL | P5: TOTAL
B7: RESUMO - DESCONTOS - EV - C 011/2026
B9: EV - C 011/2026 | C9: 46084 | D9: 523098 | E9: 3067 | F9: EVENTO CONSTRUTORA DE OBRAS | G9: 46099 | H9: 28738 | I9: AUJ- 2962 | J9: POSTO POTÊNCIA | K9: DIESEL S10 | L9: L | M9: 210.002 | N9: 5.69 | O9: 1194.9114 | P9: =M9*N9 -> 1194.9114
B10: EV - C 011/2026 | C10: 46084 | D10: 523207 | E10: 3069 | F10: EVENTO CONSTRUTORA DE OBRAS | G10: 46099 | H10: 28738 | I10: AUN7 D32 | J10: POSTO POTÊNCIA | K10: DIESEL S500 | L10: L | M10: 545.002 | N10: 5.59 | O10: 3046.5612 | P10: =M10*N10 -> 3046.5612
B11: EV - C 011/2026 | C11: 46084 | D11: 523236 | E11: 3070 | F11: EVENTO CONSTRUTORA DE OBRAS | G11: 46099 | H11: 28738 | I11: BSF5I 16 | J11: POSTO POTÊNCIA | K11: DIESEL S500 | L11: L | M11: 149.696 | N11: 5.59 | O11: 836.80064 | P11: =M11*N11 -> 836.80064
B12: EV - C 011/2026 | C12: 46084 | D12: 523602 | E12: 3074 | F12: EVENTO CONSTRUTORA DE OBRAS | G12: 46099 | H12: 28738 | I12: ATN3 B19 | J12: POSTO POTÊNCIA | K12: DIESEL S10 | L12: L | M12: 189.057 | N12: 5.69 | O12: 1075.7343 | P12: =M12*N12 -> 1075.7343
B13: EV - C 011/2026 | C13: 46084 | D13: 523606 | E13: 3075 | F13: EVENTO CONSTRUTORA DE OBRAS | G13: 46099 | H13: 28738 | I13: ERD6 B73 | J13: POSTO POTÊNCIA | K13: DIESEL S10 | L13: L | M13: 204.007 | N13: 5.69 | O13: 1160.7998 | P13: =M13*N13 -> 1160.7998
B14: EV - C 011/2026 | C14: 46084 | D14: 523612 | E14: 3076 | F14: EVENTO CONSTRUTORA DE OBRAS | G14: 46099 | H14: 28738 | I14: RXX6 A82 | J14: POSTO POTÊNCIA | K14: DIESEL S10 | L14: L | M14: 187.675 | N14: 5.69 | O14: 1067.8708 | P14: =M14*N14 -> 1067.8708
B15: EV - C 011/2026 | C15: 46084 | D15: 523612 | E15: 3077 | F15: EVENTO CONSTRUTORA DE OBRAS | G15: 46099 | H15: 28738 | I15: RXX6 A82 | J15: POSTO POTÊNCIA | K15: ARLA 32 | L15: L | M15: 14.6 | N15: 3.09 | O15: 45.114 | P15: =M15*N15 -> 45.114
B16: EV - C 011/2026 | C16: 46084 | D16: 523663 | E16: 3078 | F16: EVENTO CONSTRUTORA DE OBRAS | G16: 46099 | H16: 28738 | I16: ASE0E 48 | J16: POSTO POTÊNCIA | K16: DIESEL S10 | L16: L | M16: 185.016 | N16: 5.69 | O16: 1052.741 | P16: =M16*N16 -> 1052.741
B17: EV - C 011/2026 | C17: 46084 | D17: 524295 | E17: 3086 | F17: EVENTO CONSTRUTORA DE OBRAS | G17: 46099 | H17: 28738 | I17: APP- 8073 | J17: POSTO POTÊNCIA | K17: DIESEL S500 | L17: L | M17: 211.324 | N17: 5.69 | O17: 1202.4336 | P17: =M17*N17 -> 1202.4336
B18: EV - C 011/2026 | C18: 46084 | D18: 524295 | E18: 3087 | F18: EVENTO CONSTRUTORA DE OBRAS | G18: 46099 | H18: 28738 | I18: APP- 8073 | J18: POSTO POTÊNCIA | K18: DIESEL S500 | L18: L | M18: 2.742 | N18: 5.69 | O18: 15.61198 | P18: =M18*N18 -> 15.60198
B19: EV - C 011/2026 | C19: 46084 | D19: 524481 | E19: 3088 | F19: EVENTO CONSTRUTORA DE OBRAS | G19: 46099 | H19: 28738 | I19: ASE0E 48 | J19: POSTO POTÊNCIA | K19: DIESEL S10 | L19: L | M19: 116.877 | N19: 5.79 | O19: 676.71783 | P19: =M19*N19 -> 676.71783
B20: EV - C 011/2026 | C20: 46084 | D20: 524562 | E20: 3089 | F20: EVENTO CONSTRUTORA DE OBRAS | G20: 46099 | H20: 28738 | I20: RXX6 A82 | J20: POSTO POTÊNCIA | K20: DIESEL S10 | L20: L | M20: 201.004 | N20: 5.79 | O20: 1163.8132 | P20: =M20*N20 -> 1163.8132
... B57: EV - C 011/2026 | C57: 46111 | D57: 535277 | E57: 3245 | F57: EVENTO CONSTRUTORA DE OBRAS | G57: 46114 | H57: 29462 | I57: BEA82 | J57: POSTO POTÊNCIA | K57: DIESEL S10 | L57: L | M57: 344.004 | N57: 7.34 | O57: 2524.9894 | P57: =M57*N57 -> 2524.9894
B61: DESCONTOS - EV - C 011/2026 | O61: =SUM(O9:O60) -> 55411.25 | P61: =SUM(P9:P60) -> 55411.252
K64: DESCONTOS - EV - C 011/2026 | O64: =P61 -> 55411.252
M65: TOTAL DE DESCONTOS DES MEDIÇÃO =====>>> | O65: =SUM(O64:P64) -> 55411.252
